<?xml version="1.0"?>
<robot xmlns:xacro="http://www.ros.org/wiki/xacro">
 
  <xacro:macro name="link_axis" params="name">
    <link name="${name}">
      <inertial>
        <origin rpy="-1.57079632679 0 0" xyz="0 0 0"/>
        <mass value="0.001"/>
        <inertia ixx="6.25e-07" ixy="0.0" ixz="0.0" iyy="6.25e-07" iyz="0.0" izz="2.08333333333e-07"/>
      </inertial>
      <visual>
        <origin rpy="-1.57079632679 0 0" xyz="0 0 0"/>
        <geometry>
          <cylinder length="0.02" radius="0.0025"/>
        </geometry>
      </visual>
      <collision>
        <origin rpy="-1.57079632679 0 0" xyz="0 0 0"/>
        <geometry>
          <cylinder length="0.02" radius="0.0025"/>
        </geometry>
      </collision>
    </link>
  </xacro:macro>
  <xacro:macro name="link_chasis" params="name">
    <link name="${name}">
      <inertial>
        <origin rpy="0 0 0" xyz="0 0 0"/>
        <mass value="10"/>
        <inertia ixx="0.425" ixy="0.0" ixz="0.0" iyy="0.425" iyz="0.0" izz="0.85"/>
      </inertial>
      <visual>
        <origin rpy="0 0 0" xyz="0 0 0"/>
        <geometry>
          <cylinder length="0.08" radius="0.17"/>
        </geometry>
      <material name="iRobot/LightGrey"/>      
      </visual>
      <collision>
        <origin rpy="0 0 0" xyz="0 0 0"/>
        <geometry>
          <cylinder length="0.08" radius="0.17"/>
        </geometry>
      </collision>
    </link>
  </xacro:macro>
  <xacro:macro name="laser" params="name">
    <link name="${name}">
      <inertial>
        <origin rpy="0 0 0" xyz="0 0 0"/>
        <mass value="1e-5"/>
        <inertia ixx="1e-6" ixy="0.0" ixz="0.0" iyy="1e-6" iyz="0.0" izz="1e-6"/>
      </inertial>
      <visual>
        <origin rpy="0 0 0" xyz="0 0 0"/>
        <geometry>
          <cylinder length="0.04" radius="0.045"/>
        </geometry>
      <material name="iRobot/LightGrey"/>      
      </visual>
      <collision>
        <origin rpy="0 0 0" xyz="0 0 0"/>
        <geometry>
          <cylinder length="0.04" radius="0.045"/>
        </geometry>
      </collision>
    </link>
  </xacro:macro>     

  <xacro:macro name="link_wheel" params="name">
        <link name="${name}">
            <inertial>
              <mass value="0.2"/>
              <origin rpy="0 1.5707 1.5707" xyz="0 0 0"/>
              <inertia ixx="0.000526666666667" ixy="0" ixz="0" iyy="0.000526666666667" iyz="0" izz="0.001"/>
            </inertial>
            <collision name="link_right_wheel_collision">
              <origin rpy="0 1.5707 1.5707" xyz="0 0 0"/>
              <geometry>
                <cylinder length="0.04" radius="0.1"/>
              </geometry>
            </collision>
            <visual name="${name}_visual">
              <origin rpy="0 1.5707 1.5707" xyz="0 0 0"/>
              <geometry>
                <cylinder length="0.04" radius="0.1"/>
              </geometry>
            </visual>
        </link>
  </xacro:macro>
  <xacro:macro name="sphere" params="name">
        <link name="${name}">
            <inertial>
              <mass value="0.3"/>
              <origin rpy="0 0 0" xyz="0 0 0"/>
              <inertia ixx="0.0012" ixy="0" ixz="0" iyy="0.0012" iyz="0" izz="0.0012"/>
            </inertial>
            <collision>
              <origin rpy="0 0 0" xyz="0 0 0"/>
              <geometry>
                <sphere radius="0.01"/>
              </geometry>
            </collision>
            <visual>
              <origin rpy="0 0 0" xyz="0 0 0"/>
              <geometry>
                <sphere radius="0.01"/>
              </geometry>
              <material name="iRobot/Black"/>
            </visual>
        </link>
  </xacro:macro>  

  <xacro:macro name="joint_axis" params="name axis">
    <joint name="${name}" type="fixed">
      <origin rpy="0 0 0" xyz="${origin_xyz}"/>
      <child link="${child_1}"/>
      <parent link="chassis"/>
    </joint>
  </xacro:macro>
  <xacro:macro name="sphere_joint" params="name axis">
    <joint name="${name}" type="revolute">
      <origin rpy="0 0 0" xyz="${origin_xyz}"/>
      <child link="${child_1}"/>
      <parent link="chassis"/>
    </joint>
  </xacro:macro>  

  <xacro:macro name="joint_wheel" params="name child origin_xyz">
    <joint name="${name}" type="continuous">
      <origin rpy="0 0 0" xyz="${origin_xyz}"/>
      <child link="${child}"/>
      <parent link="${parent}"/>
      <axis rpy="0 0 0" xyz="0 1 0"/>
      <limit effort="100" velocity="100"/>
      <joint_properties damping="1.0" friction="0.5"/>
    </joint>
  </xacro:macro>

</robot>

